Workbook

Sheet Sheet2
A3: Row Labels
A4: CR
A5: (blank)
A6: (blank)
A7: (blank)
A8: (blank)
A9: MASSIMO DUTTI ESCAZU
A10: STRADIVARIUS DEL ESTE
A11: GT
A12: (blank)
A13: MASSIMO DUTTI OAKLAND
A14: (blank)
... A47: Grand Total

Sheet Sheet4
A1: SELECCIONA EL PAÍS. | B1: SV
B3: Column Labels
B4: No | E4: Total Sum of Id | F4: Total Count of Comentarios sobre la bienvenida. | G4: Total Count of ¿Se presentó a su formador?
A5: Row Labels | B5: Sum of Id | C5: Count of Comentarios sobre la bienvenida. | D5: Count of ¿Se presentó a su formador?
A6: BERSHKA LA GRAN VIA | B6: 3 | C6: 1 | D6: 1 | E6: 3 | F6: 1 | G6: 1
A7: Osiris Gabriel Moran Cuellar | B7: 3 | C7: 1 | D7: 1 | E7: 3 | F7: 1 | G7: 1
A8: ZARA LA GRAN VIA | B8: 1 | C8: 1 | D8: 1 | E8: 1 | F8: 1 | G8: 1
A9: Osiris Gabriel Moran Cuellar | B9: 1 | C9: 1 | D9: 1 | E9: 1 | F9: 1 | G9: 1
A10: Grand Total | B10: 4 | C10: 2 | D10: 2 | E10: 4 | F10: 2 | G10: 2

Sheet Sheet1
A1: Id | B1: Column1 | C1: Hora de inicio | D1: Hora de finalización | E1: Correo electrónico | F1: Nombre | G1: NOMBRE COMPLETO (ENCAGADO DE RH O RECLUTAMIENTO) | H1: ID DE COLABORADOR DEL EMPLEADO A ENTREVISTAR | I1: SELECCIONA EL PAÍS. | J1: TIENDAS EN EL SALVADOR | K1: BERSHKA GALERIAS | L1: LA GRAN VIA | M1: OFICINAS CORPORATIVAS | N1: FLYING TIGER | O1: OYSHO LA GRAN VIA | P1: PACKING SV | Q1: PULL AND BEAR GALERIAS | R1: PULL AND BEAR LA GRAN VIA | S1: STRAVARIUS GALERIAS | T1: STRADIVARIUS LA GRAN VIA | U1: ZARA LA GRAN VIA | V1: SELECCIONA TU TIENDA EN GUATEMALA | W1: BSK MIRAFLORES | X1: BSK OAKLAND | Y1: BSK PRADERA CONCEPCCIÓN | Z1: OFICINAS CORPORATIVAS1 | AA1: MASSIMO DUTTI | AB1: OYSHO OAKLAND | AC1: PACKING GT | AD1: PULL AND BEAR MIRAFLORES | AE1: PULL AND BEAR OAKLAND | AF1: PULL AND BEAR PRADERA CONCEPCIÓN | AG1: STRADIVARIUS MIRAFLORES | AH1: STRADIVARIUS OAKLAND | AI1: STRADIVARIUS PRADERA CONCEPCIÓN | AJ1: ZARA HOME GT | AK1: ZARA MIRAFLORES | AL1: ZARA OAKLAND | AM1: ZARA PRADERA CONCEPCIÓN | AN1: SELECCIONA LA TIENDA EN HONDURAS | AO1: BSK SAN PEDRO SULA | AP1: BSK TEGUCIGALPA | AQ1: MASSIMO DUTTI TEGUCIGALPA | AR1: OYSHO TEGUCIGALPA | AS1: PULL AND BEAR SAN PEDRO SULA | AT1: PULL AND BEAR TEGUCIGALPA | AU1: STRADIVARIUS SAN PEDRO SULA | AV1: STRADIVARIUS TEGUCIGALPA | AW1: ZARA CITY MALL | AX1: ZARA HOME TEGUCIGALPA | AY1: ZARA TEGUCIGALPA | AZ1: SELECCIONA TU TIENDA EN NICARAGUA | BA1: BSK SANTO DOMINGO | BB1: PULL AND BEAR SANTO DOMINGO | BC1: STRADIVARIUS SANTO DOMINGO | BD1: ZARA SANTO DOMINGO | BE1: SELECCIONA LA TIENDA DE COSTA RICA | BF1: BERSHKA MULTIPLAZA DEL ESTE | BG1: BSK MULTIPLAZA ESCAZU | BH1: ZARA HOME COSTA RICA | BI1: MASSIMO DUTTI ESCAZU | BJ1: OFICINAS CR | BK1: OYSHO ESCAZU | BL1: PULL AND BEAR DEL ESTE | BM1: PULL AND BEAR ESCAZU | BN1: STRADIVARIUS DEL ESTE | BO1: STRADIVARIUS ESCAZU | BP1: ZARA DEL ESTE | BQ1: ZARA ESCAZU | BR1: SELECCIONA EL CONTACTO | BS1: ESCRIBE EL CODIGO DE COLABORADOR | BT1: Se Sintió Bienvenido | BU1: Comentarios sobre la bienvenida. | BV1: ¿Se presentó a su formador? | BW1: Nombre del Formador | BX1: Tiene cuenta de INET y su respectiva explicación. | BY1: Que tal le pareció su induccion | BZ1: Comentarios sobre la inducción y/o adicionales | CA1: FECHA DEL SEGUNDO CONTACTO | CB1: ESCRIBE EL CÓDIGO DE COLABORADOR | CC1: NOMBRE COMPLETO | CD1: CODIGO DE COLABORADOR | CE1: ENCARGADO DE LA TIENDA | CF1: FECHA DE INGRESO | CG1: DESEMPEÑO | CH1: CUMPLE CON LAS ASIGNACIONES DE SU PUESTO | CI1: JUSTICACIÓN | CJ1: FORMACIÓN | CK1: COMENTARIOS | CL1: FECHA ESTIMADA DE TERCER CONTACTO | CM1: CÓDIGO DE COLABORADOR1 | CN1: CODIGO DE COLABORADOR1 | CO1: PUESTO | CP1: ¿Tu encargado te ha guiado adecuadamente? | CQ1: ¿Te sientes integrado/a al equipo? | CR1: ¿Recomendarías trabajar aquí? | CS1: Comentarios1 | CT1: MOTIVO DE LA BAJA | CU1: Fecha de finalización de contrato | CV1: Comentarios adicionales
A2: 1 | B2: =OfficeForms.Table[[#This Row],[SELECCIONA EL CONTACTO]] -> PRIMER CONTACTO | C2: 46108.508 | D2: 46108.509 | E2: osiris_moran@siman.com | F2: Osiris Gabriel Moran Cuellar | I2: SV | J2: ZARA LA GRAN VIA | U2: CUELLAR RIVAS, OSCAR JOEL 5207601 DEPENDIENTE | BR2: PRIMER CONTACTO | BS2: 23423 | BT2: No | BU2: 342342 | BV2: Si | BW2: 32wewre | BX2: werwe | BY2: Regular | BZ2: werwer | CA2: 46169
A3: 2 | B3: =OfficeForms.Table[[#This Row],[SELECCIONA EL CONTACTO]] -> PRIMER CONTACTO | C3: 46111.424 | D3: 46111.432 | E3: cindy_martinez@siman.com | F3: Cindy Johanna Martinez Betancourt | G3: Cindy Martinez | H3: 1234 | I3: HO | AN3: BERSHKA SAN PEDRO SULA | BR3: PRIMER CONTACTO | BS3: 1234 | BT3: Si | BU3: Todo bien | BV3: Si | BW3: Juan Perez | BX3: No aun no | BY3: Excelente | BZ3: Todo bien | CA3: 46155
A4: 3 | B4: =OfficeForms.Table[[#This Row],[SELECCIONA EL CONTACTO]] -> PRIMER CONTACTO | C4: 46111.624 | D4: 46111.625 | E4: osiris_moran@siman.com | F4: Osiris Gabriel Moran Cuellar | G4: OSIRIS MORAN | H4: 3607801 | I4: SV | J4: BERSHKA LA GRAN VIA | L4: BARAHONA CABRERA, CLARISSA SARAI DEPENDIENTE | BR4: PRIMER CONTACTO | BS4: 123 | BT4: No | BU4: no fue bienvenido solo lo mandaron a trabajar | BV4: Si | BW4: nombre de prueba | BX4: no | BY4: Muy Mala | BZ4: se adapto muy bien | CA4: 46172
A5: 4 | B5: =OfficeForms.Table[[#This Row],[SELECCIONA EL CONTACTO]] -> SEGUNDO CONTACTO | C5: 46118.42 | D5: 46118.421 | E5: osiris_moran@siman.com | F5: Osiris Gabriel Moran Cuellar | G5: osiris moran | H5: 3607801 | I5: HO | AN5: BERSHKA TEGUCIGALPA | AP5: VELASQUEZ ORELLANA, ERNESTO ENRIQUE 1284904 DEPENDIENTE | BR5: SEGUNDO CONTACTO | CB5: 2323423 | CC5: ARSDSFG | CD5: 23123 | CE5: DFSDFSD | CF5: 46113 | CG5: 7 | CH5: 7 | CI5: ASDSDA | CJ5: 7 | CK5: DFSDFS | CL5: 46181
A6: 5 | B6: =OfficeForms.Table[[#This Row],[SELECCIONA EL CONTACTO]] -> PRIMER CONTACTO | C6: 46118.455 | D6: 46118.463 | E6: lizeth_perez@siman.com | F6: Stephanie Lizeth Ballina Perez | G6: Stephanie Ballina Perez | H6: 2142703 | I6: CR | BE6: MASSIMO DUTTI ESCAZU | BI6: CORRALES RIVERA, KRISTEL DARIANA 2371703 DEPENDIENTE | BR6: PRIMER CONTACTO | BS6: 2371703 | BT6: Si | BU6: Fue muy bonita, muy cálida, tuvieron mucho entendimiento ya que era nueva. | BV6: Si | BW6: Sayling Delgado | BX6: si | BY6: Excelente
A7: 6 | B7: =OfficeForms.Table[[#This Row],[SELECCIONA EL CONTACTO]] -> PRIMER CONTACTO | C7: 46118.463 | D7: 46118.465 | E7: lizeth_perez@siman.com | F7: Stephanie Lizeth Ballina Perez | G7: Stephanie Ballina Perez | H7: 2142703 | I7: CR | BE7: MASSIMO DUTTI ESCAZU | BI7: AGUILAR GONZALEZ, KIARA SOFIA 2499503 DEPENDIENTE | BR7: PRIMER CONTACTO | BS7: 2371703 | BT7: Si | BU7: Fue una bienvenida muy tranquila ya que me explicaron todo sobre la tienda y son muy atentas todas. | BV7: Si | BW7: Nicole Navarrete | BX7: si | BY7: Excelente
B8: =OfficeForms.Table[[#This Row],[SELECCIONA EL CONTACTO]] -> PRIMER CONTACTO | BR8: PRIMER CONTACTO
A9: 7 | B9: =OfficeForms.Table[[#This Row],[SELECCIONA EL CONTACTO]] -> PRIMER CONTACTO | C9: 46118.693 | D9: 46118.694 | E9: osiris_moran@siman.com | F9: Osiris Gabriel Moran Cuellar | G9: OSIRIS MORAN| | H9: 3607801 | I9: CR | BE9: STRADIVARIUS DEL ESTE | BN9: CALDERON SANCHO, SCARLETTE PAOLA 2480703 DEPENDIENTE | BR9: PRIMER CONTACTO | BS9: 4444444 | BT9: Si | BU9: 4444 | BV9: No | BW9: SDFSDF | BX9: qeqweq | BY9: Excelente | BZ9: muy buena | CA9: 46181
A10: 8 | B10: =OfficeForms.Table[[#This Row],[SELECCIONA EL CONTACTO]] -> TERCER CONTACTO | C10: 46118.767 | D10: 46118.767 | E10: osiris_moran@siman.com | F10: Osiris Gabriel Moran Cuellar | G10: osiris moran1 | H10: 123456 | I10: GT | V10: MASSIMO DUTTI OAKLAND | AA10: MENDEZ GARCIA, DAVID ALEJANDRO 2453406 SEGUNDO ENCARGADO | BR10: TERCER CONTACTO | CM10: ewerwe | CN10: wet24 | CO10: etsda | CP10: NO | CQ10: NO | CR10: 1 | CS10: 12
B11: =OfficeForms.Table[[#This Row],[SELECCIONA EL CONTACTO]] -> 0
A12: 9 | B12: =OfficeForms.Table[[#This Row],[SELECCIONA EL CONTACTO]] -> SEGUNDO CONTACTO | C12: 46119.597 | D12: 46119.598 | E12: osiris_moran@siman.com | F12: Osiris Gabriel Moran Cuellar | G12: OSIRIS MORAN | H12: 3229106 | I12: GT | V12: BERSHKA OAKLAND | X12: NAJERA PAREDES, DERICK JOSE ANDRES 3229106 AUXILIAR DE ALMACEN | BR12: SEGUNDO CONTACTO | CB12: 3229106 | CC12: NOMBRE DE PRUEBA | CE12: ENCARGADO DE PREUBA | CF12: 46119 | CG12: 8 | CH12: 8 | CI12: HOLA | CJ12: 8 | CK12: SI SI | CL12: 46189
B13: =OfficeForms.Table[[#This Row],[SELECCIONA EL CONTACTO]] -> 0
A14: 10 | B14: =OfficeForms.Table[[#This Row],[SELECCIONA EL CONTACTO]] -> SEGUNDO CONTACTO | C14: 46119.929 | D14: 46119.93 | E14: osiris_moran@siman.com | F14: Osiris Gabriel Moran Cuellar | G14: osiris | H14: 2458003 | I14: CR | BE14: BERSHKA ESCAZU | BG14: CASTRO AGUERO, ALEXA JIREH 2458003 DEPENDIENTE | BR14: SEGUNDO CONTACTO | CB14: 2458003 | CC14: jiret | CD14: 2458003 | CE14: no se | CF14: 46113 | CG14: 9 | CH14: 7 | CI14: hola | CJ14: 8 | CK14: casito | CL14: 46181

Sheet Hoja1
A1: PAIS | B1: EMPRESA | C1: NEGOCIO | D1: CENTRO COSTO | E1: UNIDAD | F1: LUGAR TRABAJO | G1: COLABORADOR | H1: ID COLABORADOR | I1: PUESTO | J1: INGRESO | K1: RESPONSABLE UNIDAD | L1: PRIMER C
A2: Costa Rica | B2: JOVENMODA | C2: TIENDAS DE MODA | D2: GENERICO DE VENTAS PARA TIENDAS | E2: TIENDA BERSHKA DEL ESTE | F2: BERSHKA MULTIPLAZA DEL ESTE | G2: ABBOTT MUÑOZ, SOPHIA | H2: 2458303 | I2: DEPENDIENTE | J2: 46023 | K2: DOMINGUEZ SALAZAR, BLAS ARTURO | L2: =VLOOKUP(H2,Sheet1!H:H,2,0) -> #N/A
A3: Costa Rica | B3: JOVENMODA | C3: TIENDAS DE MODA | D3: GENERICO DE VENTAS PARA TIENDAS | E3: TIENDA BERSHKA DEL ESTE | F3: BERSHKA MULTIPLAZA DEL ESTE | G3: AJÚ CASTRO, MEYBEL ALEXA | H3: 2463403 | I3: DEPENDIENTE | J3: 46023 | K3: DOMINGUEZ SALAZAR, BLAS ARTURO | L3: =VLOOKUP(H3,Sheet1!H:H,1,0) -> #N/A
A4: Costa Rica | B4: JOVENMODA | C4: TIENDAS DE MODA | D4: GENERICO DE VENTAS PARA TIENDAS | E4: TIENDA BERSHKA DEL ESTE | F4: BERSHKA MULTIPLAZA DEL ESTE | G4: ARCHIBOLD LOPEZ, YOSANTIA BRITANY | H4: 2370903 | I4: DEPENDIENTE | J4: 45658 | K4: DOMINGUEZ SALAZAR, BLAS ARTURO | L4: =VLOOKUP(H4,Sheet1!H:H,1,0) -> #N/A
A5: Costa Rica | B5: JOVENMODA | C5: TIENDAS DE MODA | D5: GENERICO DE VENTAS PARA TIENDAS | E5: TIENDA BERSHKA DEL ESTE | F5: BERSHKA MULTIPLAZA DEL ESTE | G5: BADILLA MARIN, FLOR MARIA | H5: 2364303 | I5: DEPENDIENTE | J5: 45658 | K5: DOMINGUEZ SALAZAR, BLAS ARTURO | L5: =VLOOKUP(H5,Sheet1!H:H,1,0) -> #N/A
A6: Costa Rica | B6: JOVENMODA | C6: TIENDAS DE MODA | D6: GENERICO DE VENTAS PARA TIENDAS | E6: TIENDA BERSHKA DEL ESTE | F6: BERSHKA MULTIPLAZA DEL ESTE | G6: BLANCO BERMUDEZ, JOSE JULIAN | H6: 2369203 | I6: AUXILIAR DE ALMACEN | J6: 45689 | K6: DOMINGUEZ SALAZAR, BLAS ARTURO | L6: =VLOOKUP(H6,Sheet1!H:H,1,0) -> #N/A
A7: Costa Rica | B7: JOVENMODA | C7: TIENDAS DE MODA | D7: GENERICO DE VENTAS PARA TIENDAS | E7: TIENDA BERSHKA DEL ESTE | F7: BERSHKA MULTIPLAZA DEL ESTE | G7: BUSTAMANTE SANCHEZ, JOSEPH JAVIER | H7: 2194803 | I7: SEGUNDO ENCARGADO | J7: 45005 | K7: DOMINGUEZ SALAZAR, BLAS ARTURO | L7: =VLOOKUP(H7,Sheet1!H:H,1,0) -> #N/A
A8: Costa Rica | B8: JOVENMODA | C8: TIENDAS DE MODA | D8: GENERICO DE VENTAS PARA TIENDAS | E8: TIENDA BERSHKA DEL ESTE | F8: BERSHKA MULTIPLAZA DEL ESTE | G8: CHINCHILLA LOPEZ, DONALD DANIER | H8: 2306303 | I8: DEPENDIENTE | J8: 45505 | K8: DOMINGUEZ SALAZAR, BLAS ARTURO | L8: =VLOOKUP(H8,Sheet1!H:H,1,0) -> #N/A
A9: Costa Rica | B9: JOVENMODA | C9: TIENDAS DE MODA | D9: GENERICO DE VENTAS PARA TIENDAS | E9: GERENCIA DE PAIS FRANQUICIAS COSTA RICA | F9: BERSHKA MULTIPLAZA DEL ESTE | G9: DOMINGUEZ SALAZAR, BLAS ARTURO | H9: 1718003 | I9: ENCARGADO GENERAL DE TIENDA | J9: 42814 | K9: AYALA AYALA, JOSET DEL CARMEN | L9: =VLOOKUP(H9,Sheet1!H:H,1,0) -> #N/A
A10: Costa Rica | B10: JOVENMODA | C10: TIENDAS DE MODA | D10: GENERICO DE VENTAS PARA TIENDAS | E10: TIENDA BERSHKA DEL ESTE | F10: BERSHKA MULTIPLAZA DEL ESTE | G10: LAGUNA VIDAURRE, DIEGO LEONEL | H10: 2474303 | I10: AUXILIAR DE ALMACEN | J10: 46038 | K10: DOMINGUEZ SALAZAR, BLAS ARTURO | L10: =VLOOKUP(H10,Sheet1!H:H,1,0) -> #N/A
A11: Costa Rica | B11: JOVENMODA | C11: TIENDAS DE MODA | D11: GENERICO DE VENTAS PARA TIENDAS | E11: TIENDA BERSHKA DEL ESTE | F11: BERSHKA MULTIPLAZA DEL ESTE | G11: MASIS JIMENEZ, LUIS FABIAN | H11: 2444003 | I11: AUXILIAR DE ALMACEN | J11: 46023 | K11: DOMINGUEZ SALAZAR, BLAS ARTURO | L11: =VLOOKUP(H11,Sheet1!H:H,1,0) -> #N/A
A12: Costa Rica | B12: JOVENMODA | C12: TIENDAS DE MODA | D12: GENERICO DE VENTAS PARA TIENDAS | E12: TIENDA BERSHKA DEL ESTE | F12: BERSHKA MULTIPLAZA DEL ESTE | G12: MOLINA CUBERO, JORGE ANDREY | H12: 2331203 | I12: DEPENDIENTE | J12: 45614 | K12: DOMINGUEZ SALAZAR, BLAS ARTURO | L12: =VLOOKUP(H12,Sheet1!H:H,1,0) -> #N/A
A13: Costa Rica | B13: JOVENMODA | C13: TIENDAS DE MODA | D13: GENERICO DE VENTAS PARA TIENDAS | E13: TIENDA BERSHKA DEL ESTE | F13: BERSHKA MULTIPLAZA DEL ESTE | G13: PALACIOS MATAMOROS, MANUEL FRANCISCO | H13: 2494403 | I13: DEPENDIENTE | J13: 46069 | K13: DOMINGUEZ SALAZAR, BLAS ARTURO | L13: =VLOOKUP(H13,Sheet1!H:H,1,0) -> #N/A
A14: Costa Rica | B14: JOVENMODA | C14: TIENDAS DE MODA | D14: GENERICO DE VENTAS PARA TIENDAS | E14: TIENDA BERSHKA DEL ESTE | F14: BERSHKA MULTIPLAZA DEL ESTE | G14: PINEDA MURILLO, NAYARA DESSYRETH | H14: 1506903 | I14: DEPENDIENTE | J14: 42023 | K14: DOMINGUEZ SALAZAR, BLAS ARTURO | L14: =VLOOKUP(H14,Sheet1!H:H,1,0) -> #N/A
... A275: Costa Rica | B275: EUROTIENDAS | C275: TIENDAS DE MODA | D275: GENERICO DE VENTAS PARA TIENDAS | E275: TIENDA ZARA ESCAZU | F275: ZARA MULTIPLAZA ESCAZU | G275: ZELEDON CALDERÓN, DAYANA VANESSA | H275: 2511103 | I275: DEPENDIENTE | J275: 46101 | K275: NAVARRETE MORALES, DIANA KAROLINA | L275: =VLOOKUP(H275,Sheet1!H:H,1,0) -> #N/A
A276: El Salvador | B276: ESPATIENDAS | C276: TIENDAS DE MODA | D276: GENERICO DE VENTAS PARA TIENDAS | E276: TIENDA OYSHO LA GRAN VIA | F276: OYSHO LA GRAN VIA | G276: BARRIOS CACERES, DANIELA ALEJANDRA | H276: 5007101 | I276: DEPENDIENTE | J276: 46090 | L276: =VLOOKUP(H276,Sheet1!H:H,1,0) -> #N/A
A277: El Salvador | B277: ESPATIENDAS | C277: TIENDAS DE MODA | D277: GENERICO DE VENTAS PARA TIENDAS | E277: TIENDA OYSHO LA GRAN VIA | F277: OYSHO LA GRAN VIA | G277: LOVO GUEVARA, JUAN CARLOS | H277: 4728801 | I277: DEPENDIENTE | J277: 45362 | L277: =VLOOKUP(H277,Sheet1!H:H,1,0) -> #N/A
A278: El Salvador | B278: ESPATIENDAS | C278: TIENDAS DE MODA | D278: GENERICO DE VENTAS PARA TIENDAS | E278: TIENDA OYSHO LA GRAN VIA | F278: OYSHO LA GRAN VIA | G278: SOLIS TAURA, SARA REBECA | H278: 4865701 | I278: DEPENDIENTE | J278: 45705 | L278: =VLOOKUP(H278,Sheet1!H:H,1,0) -> #N/A
A279: El Salvador | B279: IBEROMODA | C279: TIENDAS DE MODA | D279: GENERICO GERENCIA | E279: PRESIDENCIA EJECUTIVA FRANQUICIAS | F279: PULL & BEAR GALERIAS | G279: AVENDAÑO OSORIO, ANTONIO | H279: 3119101 | I279: GERENTE DE SISTEMAS | J279: 43328 | K279: PORTILLO SISNIEGA, PABLO EDGARDO | L279: =VLOOKUP(H279,Sheet1!H:H,1,0) -> #N/A
A280: El Salvador | B280: PROMODA | C280: TIENDAS DE MODA | D280: GENERICO GERENCIA | E280: PRESIDENCIA EJECUTIVA FRANQUICIAS | F280: PROMODA STRADIVARIUS GALERIAS | G280: AVILA MENDEZ, EDUARDO | H280: 4972401 | I280: ANALISTA DE NEGOCIO | J280: 45670 | K280: PORTILLO SISNIEGA, PABLO EDGARDO | L280: =VLOOKUP(H280,Sheet1!H:H,1,0) -> #N/A
A281: El Salvador | B281: EUROMODA | C281: TIENDAS DE MODA | D281: GENERICO DE VENTAS PARA TIENDAS | E281: TIENDA ZARA LA GRAN VIA | F281: EUROMODA ZARA LA GRA VIA | G281: AGUILAR GARCIA, EMELY SABRINA | H281: 5034201 | I281: DEPENDIENTE | J281: 45916 | K281: SANTOS DELGADO, PATRICIA ELIZABET | L281: =VLOOKUP(H281,Sheet1!H:H,1,0) -> #N/A
A282: El Salvador | B282: EUROMODA | C282: TIENDAS DE MODA | D282: GENERICO GERENCIA | E282: GERENCIA DE OBRAS Y MANTENIMIENTO FRANQUICIAS | F282: OFICINAS CORPORATIVAS | G282: AYALA CHACON, HECTOR ENRIQUE | H282: 2302901 | I282: SUPERVISOR DE MANTENIMIENTO | J282: 45215 | K282: CHAVEZ HERNANDEZ, ARMANDO RENE | L282: =VLOOKUP(H282,Sheet1!H:H,1,0) -> #N/A
A283: El Salvador | B283: EUROMODA | C283: TIENDAS VIRTUALES | D283: GENERICO DE VENTAS PARA TIENDAS | E283: TIENDA ZARA LA GRAN VIA | F283: EUROMODA ZARA LA GRA VIA | G283: COTAN VALDEZ, GERMAN EDENILSON | H283: 3040201 | I283: RESPONSABLE DE PACKING STORE | J283: 42109 | K283: SANTOS DELGADO, PATRICIA ELIZABET | L283: =VLOOKUP(H283,Sheet1!H:H,1,0) -> #N/A
A284: El Salvador | B284: PROMODA | C284: TIENDAS DE MODA | D284: GENERICO GERENCIA | E284: PRESIDENCIA EJECUTIVA FRANQUICIAS | F284: PROMODA STRADIVARIUS GALERIAS | G284: BUCARO SALVADOR, SANDRA CAROLINA | H284: 2032901 | I284: DIRECTOR COMERCIAL DE CADENA | J284: 40483 | K284: PORTILLO SISNIEGA, PABLO EDGARDO | L284: =VLOOKUP(H284,Sheet1!H:H,1,0) -> #N/A
A285: El Salvador | B285: EUROMODA | C285: TIENDAS DE MODA | D285: GENERICO DE VENTAS PARA TIENDAS | E285: TIENDA ZARA LA GRAN VIA | F285: EUROMODA ZARA LA GRA VIA | G285: AGUILLON CASTILLO, JACQUELINE ESTHER | H285: 5200101 | I285: DEPENDIENTE | J285: 46054 | K285: SANTOS DELGADO, PATRICIA ELIZABET | L285: =VLOOKUP(H285,Sheet1!H:H,1,0) -> #N/A
A286: El Salvador | B286: EUROMODA | C286: TIENDAS DE MODA | D286: GENERICO DE VENTAS PARA TIENDAS | E286: TIENDA ZARA LA GRAN VIA | F286: EUROMODA ZARA LA GRA VIA | G286: ALVARADO MELARA, LISBETH GABRIELA | H286: 5164601 | I286: AUXILIAR DE ALMACEN | J286: 45985 | K286: SANTOS DELGADO, PATRICIA ELIZABET | L286: =VLOOKUP(H286,Sheet1!H:H,1,0) -> #N/A
A287: El Salvador | B287: EUROMODA | C287: TIENDAS DE MODA | D287: GENERICO DE VENTAS PARA TIENDAS | E287: TIENDA ZARA LA GRAN VIA | F287: EUROMODA ZARA LA GRA VIA | G287: AREVALO BLANCO, ROBERTO CHRISTOPHER | H287: 4955701 | I287: AUXILIAR DE ALMACEN | J287: 45607 | K287: SANTOS DELGADO, PATRICIA ELIZABET | L287: =VLOOKUP(H287,Sheet1!H:H,1,0) -> #N/A
A288: El Salvador | B288: EUROMODA | C288: TIENDAS DE MODA | D288: GENERICO DE VENTAS PARA TIENDAS | E288: TIENDA ZARA LA GRAN VIA | F288: EUROMODA ZARA LA GRA VIA | G288: ARGUETA GONZALEZ, ILEANA | H288: 4784501 | I288: DEPENDIENTE | J288: 45516 | K288: SANTOS DELGADO, PATRICIA ELIZABET | L288: =VLOOKUP(H288,Sheet1!H:H,1,0) -> #N/A
A289: El Salvador | B289: EUROMODA | C289: TIENDAS DE MODA | D289: GENERICO DE VENTAS PARA TIENDAS | E289: TIENDA ZARA LA GRAN VIA | F289: EUROMODA ZARA LA GRA VIA | G289: BARRERA RAMIRIOS, DANIELA TAMARA | H289: 4307701 | I289: JEFE DE OPERACIONES | J289: 44697 | K289: SANTOS DELGADO, PATRICIA ELIZABET | L289: =VLOOKUP(H289,Sheet1!H:H,1,0) -> #N/A
A290: El Salvador | B290: EUROMODA | C290: TIENDAS DE MODA | D290: GENERICO DE VENTAS PARA TIENDAS | E290: TIENDA ZARA LA GRAN VIA | F290: EUROMODA ZARA LA GRA VIA | G290: BARRIENTOS VALENZUELA, DANIELA ALEXANDRA | H290: 4710001 | I290: DEPENDIENTE | J290: 46062 | K290: SANTOS DELGADO, PATRICIA ELIZABET | L290: =VLOOKUP(H290,Sheet1!H:H,1,0) -> #N/A
... A376: El Salvador | B376: IBEROMODA | C376: TIENDAS DE MODA | D376: GENERICO GERENCIA | E376: DIRECCION DE RECURSOS HUMANOS FRANQUICIAS | F376: PULL & BEAR GALERIAS | G376: MENJIVAR QUINTANILLA, JOSE HERIBERTO | H376: 3603201 | I376: JEFE CORPORATIVO DE PREVENCION Y SALUD OCUPACIONAL | J376: 45901 | K376: GUERRERO MEDRANO, ROXANA LIZETH | L376: =VLOOKUP(H376,Sheet1!H:H,1,0) -> #N/A
A377: El Salvador | B377: JOVENMODA | C377: TIENDAS DE MODA | D377: GENERICO DE VENTAS PARA TIENDAS | E377: TIENDA BERSHKA LA GRAN VIA | F377: BERSHKA LA GRA VIA | G377: FUENTES RIVAS, JOSE ANTONIO | H377: 4789701 | I377: DEPENDIENTE | J377: 45593 | L377: =VLOOKUP(H377,Sheet1!H:H,1,0) -> #N/A
A378: El Salvador | B378: IBEROMODA | C378: TIENDAS DE MODA | D378: GENERICO GERENCIA | E378: GERENCIA DE INVENTARIOS FRANQUICIAS | F378: PULL & BEAR GALERIAS | G378: MOLINA DE ALAS, ALMA LISSETH | H378: 3820001 | I378: AUXILIAR DE CONTROL DE INVENTARIOS | J378: 43647 | K378: RIVERA RIVAS, SILVIA MARIA | L378: =VLOOKUP(H378,Sheet1!H:H,1,0) -> #N/A
A379: El Salvador | B379: JOVENMODA | C379: TIENDAS DE MODA | D379: GENERICO DE VENTAS PARA TIENDAS | E379: TIENDA BERSHKA LA GRAN VIA | F379: BERSHKA LA GRA VIA | G379: DERAS SALINAS, KEYRI ARIANA | H379: 4933801 | I379: DEPENDIENTE | J379: 45593 | L379: =VLOOKUP(H379,Sheet1!H:H,1,0) -> #N/A
A380: El Salvador | B380: JOVENMODA | C380: TIENDAS DE MODA | D380: GENERICO DE VENTAS PARA TIENDAS | E380: TIENDA BERSHKA GALERIAS | F380: BERSHKA GALERIAS | G380: OSORIO SOLORZANO, JUAN ERNESTO | H380: 4991001 | I380: DEPENDIENTE | J380: 45771 | K380: MARROQUIN PINEDA, ANDREA NICOLE | L380: =VLOOKUP(H380,Sheet1!H:H,1,0) -> #N/A
A381: El Salvador | B381: JOVENMODA | C381: TIENDAS DE MODA | D381: GENERICO DE VENTAS PARA TIENDAS | E381: TIENDA BERSHKA LA GRAN VIA | F381: BERSHKA LA GRA VIA | G381: MENJIVAR RUBIO, DIEGO ALEJANDRO | H381: 5007001 | I381: DEPENDIENTE | J381: 45831 | L381: =VLOOKUP(H381,Sheet1!H:H,1,0) -> #N/A
A382: El Salvador | B382: JOVENMODA | C382: TIENDAS DE MODA | D382: GENERICO DE VENTAS PARA TIENDAS | E382: TIENDA BERSHKA LA GRAN VIA | F382: BERSHKA LA GRA VIA | G382: RUBALLO CARDENAS, DAMARIS GISSELLE | H382: 4912801 | I382: DEPENDIENTE | J382: 45593 | L382: =VLOOKUP(H382,Sheet1!H:H,1,0) -> #N/A
A383: El Salvador | B383: JOVENMODA | C383: TIENDAS DE MODA | D383: GENERICO DE VENTAS PARA TIENDAS | E383: TIENDA BERSHKA LA GRAN VIA | F383: BERSHKA LA GRA VIA | G383: BARAHONA CABRERA, CLARISSA SARAI | H383: 4913001 | I383: DEPENDIENTE | J383: 45593 | L383: =VLOOKUP(H383,Sheet1!H:H,1,0) -> #N/A
A384: El Salvador | B384: JOVENMODA | C384: TIENDAS DE MODA | D384: GENERICO DE VENTAS PARA TIENDAS | E384: TIENDA BERSHKA GALERIAS | F384: BERSHKA GALERIAS | G384: VILLANUEVA BELTRAN, BRANDON DAGOBERTO | H384: 5117301 | I384: AUXILIAR DE ALMACEN | J384: 45957 | K384: MARROQUIN PINEDA, ANDREA NICOLE | L384: =VLOOKUP(H384,Sheet1!H:H,1,0) -> #N/A
A385: El Salvador | B385: JOVENMODA | C385: TIENDAS DE MODA | D385: GENERICO DE VENTAS PARA TIENDAS | E385: TIENDA BERSHKA LA GRAN VIA | F385: BERSHKA LA GRA VIA | G385: ALVARADO MELARA, ALEXYS GABRIEL | H385: 4913201 | I385: DEPENDIENTE | J385: 45593 | L385: =VLOOKUP(H385,Sheet1!H:H,1,0) -> #N/A
...
